[2025-01-16 19:37:52,582] {taskinstance.py:897} INFO - Dependencies not met for <TaskInstance: agile_data_science_batch_prediction_model_training.pyspark_train_classifier_model 2016-12-05T00:00:00+00:00 [up_for_retry]>, dependency 'Not In Retry Period' FAILED: Task is not ready for retry yet but will be retried automatically. Current date is 2025-01-16T18:37:52.582557+00:00 and task will be retried at 2025-01-16T18:42:47.833584+00:00.
[2025-01-16 19:37:52,583] {local_task_job.py:96} INFO - Task is not able to be run
[2025-01-16 19:44:56,254] {taskinstance.py:903} INFO - Dependencies all met for <TaskInstance: agile_data_science_batch_prediction_model_training.pyspark_train_classifier_model 2016-12-05T00:00:00+00:00 [queued]>
[2025-01-16 19:44:56,277] {taskinstance.py:903} INFO - Dependencies all met for <TaskInstance: agile_data_science_batch_prediction_model_training.pyspark_train_classifier_model 2016-12-05T00:00:00+00:00 [queued]>
[2025-01-16 19:44:56,277] {taskinstance.py:1095} INFO - 
--------------------------------------------------------------------------------
[2025-01-16 19:44:56,278] {taskinstance.py:1096} INFO - Starting attempt 2 of 4
[2025-01-16 19:44:56,279] {taskinstance.py:1097} INFO - 
--------------------------------------------------------------------------------
[2025-01-16 19:44:56,453] {taskinstance.py:1115} INFO - Executing <Task(BashOperator): pyspark_train_classifier_model> on 2016-12-05T00:00:00+00:00
[2025-01-16 19:44:56,469] {standard_task_runner.py:52} INFO - Started process 319985 to run task
[2025-01-16 19:44:56,484] {standard_task_runner.py:76} INFO - Running: ['airflow', 'tasks', 'run', 'agile_data_science_batch_prediction_model_training', 'pyspark_train_classifier_model', '2016-12-05T00:00:00+00:00', '--job-id', '20', '--pool', 'default_pool', '--raw', '--subdir', 'DAGS_FOLDER/setup.py', '--cfg-path', '/tmp/tmpovjkvcq5', '--error-file', '/tmp/tmp4jzkbh01']
[2025-01-16 19:44:56,486] {standard_task_runner.py:77} INFO - Job 20: Subtask pyspark_train_classifier_model
[2025-01-16 19:44:56,614] {logging_mixin.py:109} INFO - Running <TaskInstance: agile_data_science_batch_prediction_model_training.pyspark_train_classifier_model 2016-12-05T00:00:00+00:00 [running]> on host ibdn-VirtualBox
[2025-01-16 19:44:56,683] {taskinstance.py:1254} INFO - Exporting the following env vars:
AIRFLOW_CTX_DAG_OWNER=airflow
AIRFLOW_CTX_DAG_ID=agile_data_science_batch_prediction_model_training
AIRFLOW_CTX_TASK_ID=pyspark_train_classifier_model
AIRFLOW_CTX_EXECUTION_DATE=2016-12-05T00:00:00+00:00
AIRFLOW_CTX_DAG_RUN_ID=scheduled__2016-12-05T00:00:00+00:00
[2025-01-16 19:44:56,685] {subprocess.py:52} INFO - Tmp dir root location: 
 /tmp
[2025-01-16 19:44:56,686] {subprocess.py:63} INFO - Running command: ['bash', '-c', '\nspark-submit --master local[8]   /home/ibdn/BDFI/practica_creativa//resources/train_spark_mllib_model.py   /home/ibdn/BDFI/practica_creativa/']
[2025-01-16 19:44:56,694] {subprocess.py:74} INFO - Output:
[2025-01-16 19:45:01,640] {local_task_job.py:204} WARNING - Recorded pid 320086 does not match the current pid 319985
[2025-01-16 19:45:01,681] {process_utils.py:100} INFO - Sending Signals.SIGTERM to GPID 319985
[2025-01-16 19:45:01,682] {taskinstance.py:1236} ERROR - Received SIGTERM. Terminating subprocesses.
[2025-01-16 19:45:01,682] {subprocess.py:88} INFO - Sending SIGTERM signal to process group
[2025-01-16 19:45:01,734] {taskinstance.py:1463} ERROR - Task failed with exception
Traceback (most recent call last):
  File "/home/ibdn/.local/lib/python3.7/site-packages/airflow/models/taskinstance.py", line 1165, in _run_raw_task
    self._prepare_and_execute_task_with_callbacks(context, task)
  File "/home/ibdn/.local/lib/python3.7/site-packages/airflow/models/taskinstance.py", line 1283, in _prepare_and_execute_task_with_callbacks
    result = self._execute_task(context, task_copy)
  File "/home/ibdn/.local/lib/python3.7/site-packages/airflow/models/taskinstance.py", line 1313, in _execute_task
    result = task_copy.execute(context=context)
  File "/home/ibdn/.local/lib/python3.7/site-packages/airflow/operators/bash.py", line 171, in execute
    output_encoding=self.output_encoding,
  File "/home/ibdn/.local/lib/python3.7/site-packages/airflow/hooks/subprocess.py", line 76, in run_command
    for raw_line in iter(self.sub_process.stdout.readline, b''):
  File "/home/ibdn/.local/lib/python3.7/site-packages/airflow/models/taskinstance.py", line 1238, in signal_handler
    raise AirflowException("Task received SIGTERM signal")
airflow.exceptions.AirflowException: Task received SIGTERM signal
[2025-01-16 19:45:01,774] {taskinstance.py:1513} INFO - Marking task as UP_FOR_RETRY. dag_id=agile_data_science_batch_prediction_model_training, task_id=pyspark_train_classifier_model, execution_date=20161205T000000, start_date=20250116T184500, end_date=20250116T184501
[2025-01-16 19:45:01,939] {process_utils.py:66} INFO - Process psutil.Process(pid=319985, status='terminated', exitcode=1, started='19:44:56') (319985) terminated with exit code 1
[2025-01-16 19:45:01,939] {process_utils.py:66} INFO - Process psutil.Process(pid=320007, status='terminated', started='19:44:56') (320007) terminated with exit code None
[2025-01-16 19:45:01,940] {process_utils.py:66} INFO - Process psutil.Process(pid=320006, status='terminated', started='19:44:56') (320006) terminated with exit code None
